Workbook

Sheet List1
A1: Компания | B1: № | C1: Ф.И.О. | D1: Контактный номер | E1: Дата Заказа | F1: Дата доставки | G1: ID | H1: Оператор (ПИН) | I1: Bo'lim | J1: Товар1 | K1: кол-во1 | L1: Товар2 | M1: кол-во2 | N1: Товар3 | O1: кол-во3 | P1: Сумма | Q1: Регион | R1: Адрес | S1: статус | T1: Логистика | U1: Контакт | V1: Источник
A2: Шифодор корп | B2: 21882 | C2: Гулайым | D2: 913865022 936803223 | E2: 45931 | G2: 0023 | H2: =IFERROR(VLOOKUP(G2,List2!$B$2:$C$100,2,FALSE), "Kerkali xodim topilmadi") -> NIGORA MAMATQULOVNA | I2: =IFERROR(VLOOKUP(G2,List2!$B$2:$D$100,3,FALSE), "Kerkali BO'LIM topilmadi") -> Baza | J2: Vagina Angusta | K2: 3 | P2: 900000 | Q2: Каракалпакстан | R2: Нукус shaxar,N Tulayev 36 | S2: Успешно | T2: Караван | U2: база
A3: Шифодор корп | B3: 21883 | C3: Feruza | D3: 880700036, 959757413 | E3: 45931 | G3: 0021 | H3: =IFERROR(VLOOKUP(G3,List2!$B$2:$C$100,2,FALSE), "Kerkali xodim topilmadi") -> IRODA ABDULAZIZOVNA | I3: =IFERROR(VLOOKUP(G3,List2!$B$2:$D$100,3,FALSE), "Kerkali BO'LIM topilmadi") -> Gynocology | J3: Vagina Angusta | K3: 4 | P3: 1050000 | Q3: Кашкадаринская област | R3: Qarshi shahar ISLOM KARIMOV KO'CHA SOXIL OLDI 442 DO'M 26 UY | S3: Успешно | T3: Караван | U3: первичный | V3: Akobir_target
A4: Шифодор корп | B4: 21884 | C4: Umida | D4: 507118188 | E4: 45931 | G4: 0034 | H4: =IFERROR(VLOOKUP(G4,List2!$B$2:$C$100,2,FALSE), "Kerkali xodim topilmadi") -> SARVINOZ TOXIROVNA | I4: =IFERROR(VLOOKUP(G4,List2!$B$2:$D$100,3,FALSE), "Kerkali BO'LIM topilmadi") -> A | J4: Vagina Angusta | K4: 2 | P4: 700000 | Q4: Город Ташкент | R4: CHILONZOR 19 ARENTIR BELISSIMO | S4: Отказ | T4: Караван | U4: первичный | V4: Ayubxon
A5: Шифодор корп | B5: 21885 | C5: Muxarram | D5: 938603336 | E5: 45931 | G5: 0018 | H5: =IFERROR(VLOOKUP(G5,List2!$B$2:$C$100,2,FALSE), "Kerkali xodim topilmadi") -> DILSHODA NORQUVONONA | I5: =IFERROR(VLOOKUP(G5,List2!$B$2:$D$100,3,FALSE), "Kerkali BO'LIM topilmadi") -> Gynocology | J5: Vagina Angusta | K5: 5 | P5: 1200000 | Q5: Город Ташкент | R5: olmazor xastiiymon 28 maktab maxbara | S5: Успешно | T5: Караван | U5: первичный
A6: Шифодор корп | B6: 21886 | C6: Saydullayeva Gulxayo | D6: 88 1020228 | E6: 45931 | G6: 0018 | H6: =IFERROR(VLOOKUP(G6,List2!$B$2:$C$100,2,FALSE), "Kerkali xodim topilmadi") -> DILSHODA NORQUVONONA | I6: =IFERROR(VLOOKUP(G6,List2!$B$2:$D$100,3,FALSE), "Kerkali BO'LIM topilmadi") -> Gynocology | J6: Vagina Angusta | K6: 4 | P6: 1050000 | Q6: Город Ташкент | R6: olmazor seti 51 daxa | S6: Отказ | T6: Караван | U6: первичный | V6: Ayubxon
A7: Шифодор корп | B7: 21887 | C7: саодат | D7: 944039204 | E7: 45931 | G7: 0018 | H7: =IFERROR(VLOOKUP(G7,List2!$B$2:$C$100,2,FALSE), "Kerkali xodim topilmadi") -> DILSHODA NORQUVONONA | I7: =IFERROR(VLOOKUP(G7,List2!$B$2:$D$100,3,FALSE), "Kerkali BO'LIM topilmadi") -> Gynocology | J7: Vagina Angusta | K7: 5 | P7: 1200000 | Q7: Ташкентская область | R7: PISKENT TUMANI DUNGQURG`ON MFY | S7: Успешно | T7: Караван | U7: первичный | V7: Akobir_target
A8: Шифодор корп | B8: 21888 | C8: Mahliyo | D8: 930911603 | E8: 45931 | G8: 0018 | H8: =IFERROR(VLOOKUP(G8,List2!$B$2:$C$100,2,FALSE), "Kerkali xodim topilmadi") -> DILSHODA NORQUVONONA | I8: =IFERROR(VLOOKUP(G8,List2!$B$2:$D$100,3,FALSE), "Kerkali BO'LIM topilmadi") -> Gynocology | J8: Vagina Angusta | K8: 4 | P8: 1050000 | Q8: Самаркандская область | R8: bulung`ur tumani | S8: Отказ | T8: Караван | U8: первичный | V8: Akobir_target
A9: Шифодор корп | B9: 21889 | C9: Зуля раббимова | D9: 917020730 | E9: 45931 | G9: 0017 | H9: =IFERROR(VLOOKUP(G9,List2!$B$2:$C$100,2,FALSE), "Kerkali xodim topilmadi") -> ZAMIRA MELISOVNA | I9: =IFERROR(VLOOKUP(G9,List2!$B$2:$D$100,3,FALSE), "Kerkali BO'LIM topilmadi") -> Baza | J9: Vagina Angusta | K9: 4 | P9: 1100000 | Q9: Самаркандская область | R9: САМАРКАНД Ш КАПТАРХОНА ОВАШНОЙ | S9: Успешно | T9: Караван | U9: первичный | V9: Akobir_target
A10: Шифодор корп | B10: 21890 | C10: Surayyo Bozoriva | D10: 950549594 | E10: 45931 | G10: 0020 | H10: =IFERROR(VLOOKUP(G10,List2!$B$2:$C$100,2,FALSE), "Kerkali xodim topilmadi") -> LOBAR QO'LDOSHEVNA | I10: =IFERROR(VLOOKUP(G10,List2!$B$2:$D$100,3,FALSE), "Kerkali BO'LIM topilmadi") -> Gynocology | J10: Vagina Angusta | K10: 4 | P10: 1050000 | Q10: Город Ташкент | R10: CHILONZOR 19,AVTOWKOLA YONIDA,3 DOM | S10: Успешно | T10: Караван | U10: первичный | V10: Ayubxon
A11: Шифодор корп | B11: 21891 | C11: dildor24.07.89 | D11: 507590007 | E11: 45931 | G11: 0021 | H11: =IFERROR(VLOOKUP(G11,List2!$B$2:$C$100,2,FALSE), "Kerkali xodim topilmadi") -> IRODA ABDULAZIZOVNA | I11: =IFERROR(VLOOKUP(G11,List2!$B$2:$D$100,3,FALSE), "Kerkali BO'LIM topilmadi") -> Gynocology | J11: Vagina Angusta | K11: 4 | P11: 1050000 | Q11: Наманганская область | R11: UYCHI TUMANI BERUNI MAXALLA AMIR TEMUR KO'CHA 7 DOM 4 XONADON | S11: Отказ | T11: Караван | U11: первичный | V11: Ayubxon
A12: Шифодор корп | B12: 21892 | C12: Зайнаб Каршибоева | D12: 93 037 10 65 | E12: 45931 | G12: 0019 | H12: =IFERROR(VLOOKUP(G12,List2!$B$2:$C$100,2,FALSE), "Kerkali xodim topilmadi") -> NIGORA G'ULOMOVNA | I12: =IFERROR(VLOOKUP(G12,List2!$B$2:$D$100,3,FALSE), "Kerkali BO'LIM topilmadi") -> Gynocology | J12: Vagina Angusta | K12: 4 | P12: 1050000 | Q12: Джизахская область | R12: Зарбдор тумани Равот махалласи Тиллакор кучаси | S12: Отказ | T12: Караван | U12: первичный | V12: Ayubxon
A13: Шифодор корп | B13: 21893 | C13: guldora annaqulova | D13: 507066684, 941865225 | E13: 45931 | G13: 0035 | H13: =IFERROR(VLOOKUP(G13,List2!$B$2:$C$100,2,FALSE), "Kerkali xodim topilmadi") -> FOTIMA NOSIRBAYEVNA | I13: =IFERROR(VLOOKUP(G13,List2!$B$2:$D$100,3,FALSE), "Kerkali BO'LIM topilmadi") -> A | J13: Vagina Angusta | K13: 4 | P13: 1050000 | Q13: Самаркандская область | R13: kattaqorgon tumani melahoja mahallasi tong qorgon paselkasi | S13: Успешно | T13: Караван | U13: первичный | V13: Ayubxon
A14: Шифодор корп | B14: 21894 | C14: Adolat Eshpulatova | D14: 932323037 | E14: 45931 | G14: 0035 | H14: =IFERROR(VLOOKUP(G14,List2!$B$2:$C$100,2,FALSE), "Kerkali xodim topilmadi") -> FOTIMA NOSIRBAYEVNA | I14: =IFERROR(VLOOKUP(G14,List2!$B$2:$D$100,3,FALSE), "Kerkali BO'LIM topilmadi") -> A | J14: Vagina Angusta | K14: 4 | P14: 1000000 | Q14: Наваинская область | R14: zarafshon shahar yangi zafar mahallasi 6 kvartal 44 uy | S14: Успешно | T14: Караван | U14: первичный | V14: Ayubxon
A15: Шифодор корп | B15: 21895 | C15: Ro'za Axmedova | D15: 942429697 | E15: 45931 | G15: 0019 | H15: =IFERROR(VLOOKUP(G15,List2!$B$2:$C$100,2,FALSE), "Kerkali xodim topilmadi") -> NIGORA G'ULOMOVNA | I15: =IFERROR(VLOOKUP(G15,List2!$B$2:$D$100,3,FALSE), "Kerkali BO'LIM topilmadi") -> Gynocology | J15: Vagina Angusta | K15: 6 | P15: 1300000 | Q15: Харезмская область | R15: Хазорасп тумани Карвак кишлоги Мироп туйхона енига | S15: Успешно | T15: Караван | U15: первичный | V15: Ayubxon
A16: Шифодор корп | B16: 21896 | C16: Dildora | D16: 940790290 | E16: 45931 | G16: 0047 | H16: =IFERROR(VLOOKUP(G16,List2!$B$2:$C$100,2,FALSE), "Kerkali xodim topilmadi") -> XILOLA TURG'UNOVNA | I16: =IFERROR(VLOOKUP(G16,List2!$B$2:$D$100,3,FALSE), "Kerkali BO'LIM topilmadi") -> Gynocology | J16: Vagina Angusta | K16: 4 | P16: 1050000 | Q16: Джизахская область | R16: Зомин тумани Боги шамол мах. Садаф кучаси 26 уй | S16: Отказ | T16: Караван | U16: первичный | V16: Ayubxon
A17: Шифодор корп | B17: 21897 | C17: Zumratoy | D17: 977462112 | E17: 45931 | G17: 0018 | H17: =IFERROR(VLOOKUP(G17,List2!$B$2:$C$100,2,FALSE), "Kerkali xodim topilmadi") -> DILSHODA NORQUVONONA | I17: =IFERROR(VLOOKUP(G17,List2!$B$2:$D$100,3,FALSE), "Kerkali BO'LIM topilmadi") -> Gynocology | J17: Vagina Angusta | K17: 4 | P17: 1050000 | Q17: Ферганская область | R17: quvadan paxtakor mfy 105 uy | S17: Отказ | T17: Караван | U17: первичный | V17: Ayubxon
A18: Шифодор корп | B18: 21898 | C18: sarvňoz | D18: 952355227 | E18: 45931 | G18: 0035 | H18: =IFERROR(VLOOKUP(G18,List2!$B$2:$C$100,2,FALSE), "Kerkali xodim topilmadi") -> FOTIMA NOSIRBAYEVNA | I18: =IFERROR(VLOOKUP(G18,List2!$B$2:$D$100,3,FALSE), "Kerkali BO'LIM topilmadi") -> A | J18: Vagina Angusta | K18: 4 | P18: 1050000 | Q18: Самаркандская область | R18: urgut tumani ispanza mahallasi 11uy | S18: Успешно | T18: Караван | U18: первичный | V18: Akobir_target
A19: Шифодор корп | B19: 21899 | C19: севара боймирзаева 2002 4 ногябрь | D19: 93 456 66 04, 953605107 | E19: 45931 | G19: 0017 | H19: =IFERROR(VLOOKUP(G19,List2!$B$2:$C$100,2,FALSE), "Kerkali xodim topilmadi") -> ZAMIRA MELISOVNA | I19: =IFERROR(VLOOKUP(G19,List2!$B$2:$D$100,3,FALSE), "Kerkali BO'LIM topilmadi") -> Baza | J19: Vagina Angusta | K19: 6 | P19: 1300000 | Q19: Кашкадаринская област | R19: кашкадарье чирокчи кукдаля этитом мах | S19: Отказ | T19: Караван | U19: первичный | V19: Akobir_target
A20: Шифодор корп | B20: 21900 | C20: chirch MAYRAM | D20: 971144478 | E20: 45931 | G20: 0018 | H20: =IFERROR(VLOOKUP(G20,List2!$B$2:$C$100,2,FALSE), "Kerkali xodim topilmadi") -> DILSHODA NORQUVONONA | I20: =IFERROR(VLOOKUP(G20,List2!$B$2:$D$100,3,FALSE), "Kerkali BO'LIM topilmadi") -> Gynocology | J20: Vagina Angusta | K20: 4 | P20: 1050000 | Q20: Ташкентская область | R20: chirchiq tumani | S20: Отказ | T20: Караван | U20: первичный | V20: Ayubxon
H81: =IFERROR(VLOOKUP(G81,List2!$B$2:$C$100,2,FALSE), "Kerkali xodim topilmadi") -> Kerkali xodim topilmadi | I81: =IFERROR(VLOOKUP(G81,List2!$B$2:$D$100,3,FALSE), "Kerkali BO'LIM topilmadi") -> Kerkali BO'LIM topilmadi
H82: =IFERROR(VLOOKUP(G82,List2!$B$2:$C$100,2,FALSE), "Kerkali xodim topilmadi") -> Kerkali xodim topilmadi | I82: =IFERROR(VLOOKUP(G82,List2!$B$2:$D$100,3,FALSE), "Kerkali BO'LIM topilmadi") -> Kerkali BO'LIM topilmadi
H83: =IFERROR(VLOOKUP(G83,List2!$B$2:$C$100,2,FALSE), "Kerkali xodim topilmadi") -> Kerkali xodim topilmadi | I83: =IFERROR(VLOOKUP(G83,List2!$B$2:$D$100,3,FALSE), "Kerkali BO'LIM topilmadi") -> Kerkali BO'LIM topilmadi
H84: =IFERROR(VLOOKUP(G84,List2!$B$2:$C$100,2,FALSE), "Kerkali xodim topilmadi") -> Kerkali xodim topilmadi | I84: =IFERROR(VLOOKUP(G84,List2!$B$2:$D$100,3,FALSE), "Kerkali BO'LIM topilmadi") -> Kerkali BO'LIM topilmadi
H85: =IFERROR(VLOOKUP(G85,List2!$B$2:$C$100,2,FALSE), "Kerkali xodim topilmadi") -> Kerkali xodim topilmadi | I85: =IFERROR(VLOOKUP(G85,List2!$B$2:$D$100,3,FALSE), "Kerkali BO'LIM topilmadi") -> Kerkali BO'LIM topilmadi
H86: =IFERROR(VLOOKUP(G86,List2!$B$2:$C$100,2,FALSE), "Kerkali xodim topilmadi") -> Kerkali xodim topilmadi | I86: =IFERROR(VLOOKUP(G86,List2!$B$2:$D$100,3,FALSE), "Kerkali BO'LIM topilmadi") -> Kerkali BO'LIM topilmadi
H87: =IFERROR(VLOOKUP(G87,List2!$B$2:$C$100,2,FALSE), "Kerkali xodim topilmadi") -> Kerkali xodim topilmadi | I87: =IFERROR(VLOOKUP(G87,List2!$B$2:$D$100,3,FALSE), "Kerkali BO'LIM topilmadi") -> Kerkali BO'LIM topilmadi
H88: =IFERROR(VLOOKUP(G88,List2!$B$2:$C$100,2,FALSE), "Kerkali xodim topilmadi") -> Kerkali xodim topilmadi | I88: =IFERROR(VLOOKUP(G88,List2!$B$2:$D$100,3,FALSE), "Kerkali BO'LIM topilmadi") -> Kerkali BO'LIM topilmadi
H89: =IFERROR(VLOOKUP(G89,List2!$B$2:$C$100,2,FALSE), "Kerkali xodim topilmadi") -> Kerkali xodim topilmadi | I89: =IFERROR(VLOOKUP(G89,List2!$B$2:$D$100,3,FALSE), "Kerkali BO'LIM topilmadi") -> Kerkali BO'LIM topilmadi
H90: =IFERROR(VLOOKUP(G90,List2!$B$2:$C$100,2,FALSE), "Kerkali xodim topilmadi") -> Kerkali xodim topilmadi | I90: =IFERROR(VLOOKUP(G90,List2!$B$2:$D$100,3,FALSE), "Kerkali BO'LIM topilmadi") -> Kerkali BO'LIM topilmadi
H91: =IFERROR(VLOOKUP(G91,List2!$B$2:$C$100,2,FALSE), "Kerkali xodim topilmadi") -> Kerkali xodim topilmadi | I91: =IFERROR(VLOOKUP(G91,List2!$B$2:$D$100,3,FALSE), "Kerkali BO'LIM topilmadi") -> Kerkali BO'LIM topilmadi
H92: =IFERROR(VLOOKUP(G92,List2!$B$2:$C$100,2,FALSE), "Kerkali xodim topilmadi") -> Kerkali xodim topilmadi | I92: =IFERROR(VLOOKUP(G92,List2!$B$2:$D$100,3,FALSE), "Kerkali BO'LIM topilmadi") -> Kerkali BO'LIM topilmadi
... H425: =IFERROR(VLOOKUP(G425,List2!$B$2:$C$100,2,FALSE), "Kerkali xodim topilmadi") -> Kerkali xodim topilmadi | I425: =IFERROR(VLOOKUP(G425,List2!$B$2:$D$100,3,FALSE), "Kerkali BO'LIM topilmadi") -> Kerkali BO'LIM topilmadi
X426: 23427

Sheet List2
A1: № | B1: ID | C1: XODIMLAR ISMLARI | D1: Bo'lim | E1: Umumiy zakaz summasi | F1: Первичный Заказ | G1: База | H1: Otkaz | I1: В процесс | J1: Upakovka soni | K1: OYLIK MOASH | L1: Konversiya
A2: 1 | B2: 0001 | C2: ELBEK XAYDAROV | D2: A | E2: 190455000 | F2: 87175000 | G2: 0 | H2: 103280000 | I2: 0 | J2: 116 | K2: =F2*12%+G2*16% -> 10461000 | L2: =(F2+G2)/E2 -> 0.45771967
A3: 2 | B3: 0002 | C3: SAMANDAR CHORIYEV | D3: A | E3: 0 | F3: 0 | G3: 0 | H3: 0 | I3: 0 | J3: 0 | K3: =F3*12%+G3*16% -> 0 | L3: =(F3+G3)/E3 -> #DIV/0!
A4: 3 | B4: 0003 | C4: LAZIZBEK ABDURAXMONOV | D4: A | E4: 42185000 | F4: 32035000 | G4: 0 | H4: 10150000 | I4: 0 | J4: 46 | K4: =F4*12%+G4*16% -> 3844200 | L4: =(F4+G4)/E4 -> 0.75939315
A5: 4 | B5: 0004 | C5: INOMJON JO'RAQO'ZIYEV | D5: A | E5: 62470000 | F5: 39090000 | G5: 0 | H5: 23380000 | I5: 0 | J5: 55 | K5: =F5*12%+G5*16% -> 4690800 | L5: =(F5+G5)/E5 -> 0.62574036
A6: 5 | B6: 0005 | C6: SHAXNOZA XOLTURAEVA | D6: A | E6: 49745000 | F6: 38770000 | G6: 0 | H6: 10975000 | I6: 0 | J6: 55 | K6: =F6*12%+G6*16% -> 4652400 | L6: =(F6+G6)/E6 -> 0.77937481
A7: 6 | B7: 0006 | C7: USMONXO'JA QAYUMXO'JAEV | D7: A | E7: 141570000 | F7: 100990000 | G7: 0 | H7: 40580000 | I7: 0 | J7: 140 | K7: =F7*12%+G7*16% -> 12118800 | L7: =(F7+G7)/E7 -> 0.71335735
A8: 7 | B8: 0007 | C8: IRODA XAKIMOVA | D8: B | E8: 102755000 | F8: 34365000 | G8: 0 | H8: 68390000 | I8: 0 | J8: 52 | K8: =F8*12%+G8*16% -> 4123800 | L8: =(F8+G8)/E8 -> 0.33443628
A9: 8 | B9: 0008 | C9: NOZIMA JAMOLIDDINOVA | D9: Baza | E9: 4450000 | F9: 1450000 | G9: 1150000 | H9: 1850000 | I9: 0 | J9: 5 | K9: =F9*12%+G9*16% -> 358000 | L9: =(F9+G9)/E9 -> 0.58426966
A10: 9 | B10: 0009 | C10: ROBIYA ABDULXAMIDOVA | D10: A | E10: 0 | F10: 0 | G10: 0 | H10: 0 | I10: 0 | J10: 0 | K10: =F10*12%+G10*16% -> 0 | L10: =(F10+G10)/E10 -> #DIV/0!
A11: 10 | B11: 0010 | C11: SHAXRIYOR ZOKIRJONOV | D11: A | E11: 37830000 | F11: 25510000 | G11: 0 | H11: 12320000 | I11: 0 | J11: 37 | K11: =F11*12%+G11*16% -> 3061200 | L11: =(F11+G11)/E11 -> 0.67433254
A12: 11 | B12: 0011 | C12: DILSHODBEK AXMADOV | D12: A | E12: 47110000 | F12: 26255000 | G12: 0 | H12: 20855000 | I12: 0 | J12: 36 | K12: =F12*12%+G12*16% -> 3150600 | L12: =(F12+G12)/E12 -> 0.55731267
A13: 12 | B13: 0012 | C13: ASADBEK BOQIJONOV | D13: A | E13: 10560000 | F13: 7540000 | G13: 0 | H13: 3020000 | I13: 0 | J13: 10 | K13: =F13*12%+G13*16% -> 904800 | L13: =(F13+G13)/E13 -> 0.71401515
... A61: 60 | B61: 0060 | C61: MADINA | D61: A | E61: 5240000 | F61: 3625000 | G61: 0 | H61: 1615000 | I61: 0 | J61: 5 | K61: =F61*12%+G61*16% -> 435000 | L61: =(F61+G61)/E61 -> 0.69179389
A62: 61 | B62: 0061 | C62: BONU MURODOVA | D62: A | E62: 600000 | F62: 600000 | G62: 0 | H62: 0 | I62: 0 | J62: 1 | K62: =F62*12%+G62*16% -> 72000 | L62: =(F62+G62)/E62 -> 1 | M62: 27
A63: 62 | B63: 0062 | C63: OLIM MO'MINOV | D63: C | E63: 10285000 | F63: 2390000 | G63: 0 | H63: 7895000 | I63: 0 | J63: 3 | K63: =F63*12%+G63*16% -> 286800 | L63: =(F63+G63)/E63 -> 0.23237725
A64: 63 | B64: 0063 | C64: SHOXRUX ABDULLAYEV | D64: C | E64: 3025000 | F64: 2200000 | G64: 0 | H64: 825000 | I64: 0 | J64: 3 | K64: =F64*12%+G64*16% -> 264000 | L64: =(F64+G64)/E64 -> 0.72727273
A65: 64 | B65: 0064 | C65: ERMATOVA HILOLA | D65: C | E65: 780000 | F65: 780000 | G65: 0 | H65: 0 | I65: 0 | J65: 1 | K65: =F65*12%+G65*16% -> 93600 | L65: =(F65+G65)/E65 -> 1
A66: 65 | B66: 0065 | C66: TALATJONOV NURMUHAMMAD | D66: A | E66: 600000 | F66: 600000 | G66: 0 | H66: 0 | I66: 0 | J66: 1 | K66: =F66*12%+G66*16% -> 72000 | L66: =(F66+G66)/E66 -> 1 | M66: =L66+L62+L61+L55+L53+L52+L49+L46+L44+L43+L41+L40+L39+L36+L35+L26+L16+L15+L14+L13+L12+L11+L7+L6+L5+L4+L2 -> 18.218819 | N66: =M66/M62 -> 0.67477108
A67: 66 | B67: 0066 | C67: BABAYEV BAXTIYOR | D67: C | E67: 825000 | F67: 825000 | G67: 0 | H67: 0 | I67: 0 | J67: 1 | K67: =F67*12%+G67*16% -> 99000 | L67: =(F67+G67)/E67 -> 1
A68: 67 | B68: 0067 | C68: XOLDAROV AXROR | D68: C | E68: 9635000 | F68: 6335000 | G68: 0 | H68: 3300000 | I68: 0 | J68: 8 | K68: =F68*12%+G68*16% -> 760200 | L68: =(F68+G68)/E68 -> 0.6574987
A69: 68 | B69: 0068 | C69: TEMEROV ALIBEK | D69: C | E69: 3725000 | F69: 1525000 | G69: 0 | H69: 2200000 | I69: 0 | J69: 2 | K69: =F69*12%+G69*16% -> 183000 | L69: =(F69+G69)/E69 -> 0.40939597
A70: 69 | B70: 0069 | C70: RADJABOVA DILRABO | D70: BAZA | E70: 0 | F70: 0 | G70: 0 | H70: 0 | I70: 0 | J70: 0 | K70: =F70*12%+G70*16% -> 0 | L70: =(F70+G70)/E70 -> #DIV/0!
A71: 70 | B71: 0070 | E71: 0 | F71: 0 | G71: 0 | H71: 0 | I71: 0 | J71: 0 | K71: =F71*12%+G71*16% -> 0 | L71: =(F71+G71)/E71 -> #DIV/0!
A72: 71 | B72: 0071 | E72: 0 | F72: 0 | G72: 0 | H72: 0 | I72: 0 | J72: 0 | K72: =F72*12%+G72*16% -> 0 | L72: =(F72+G72)/E72 -> #DIV/0!
A73: 72 | B73: 0072 | E73: 0 | F73: 0 | G73: 0 | H73: 0 | I73: 0 | J73: 0 | K73: =F73*12%+G73*16% -> 0 | L73: =(F73+G73)/E73 -> #DIV/0!
A74: 73 | B74: 0073 | E74: 0 | F74: 0 | G74: 0 | H74: 0 | I74: 0 | J74: 0 | K74: =F74*12%+G74*16% -> 0 | L74: =(F74+G74)/E74 -> #DIV/0!
A75: 74 | B75: 0074 | E75: 0 | F75: 0 | G75: 0 | H75: 0 | I75: 0 | J75: 0 | K75: =F75*12%+G75*16% -> 0 | L75: =(F75+G75)/E75 -> #DIV/0!
A76: 75 | B76: 0075 | E76: 0 | F76: 0 | G76: 0 | H76: 0 | I76: 0 | J76: 0 | K76: =F76*12%+G76*16% -> 0 | L76: =(F76+G76)/E76 -> #DIV/0!
A77: 76 | B77: 0076 | E77: 0 | F77: 0 | G77: 0 | H77: 0 | I77: 0 | J77: 0 | K77: =F77*12%+G77*16% -> 0 | L77: =(F77+G77)/E77 -> #DIV/0!
A78: 77 | B78: 0077 | E78: 0 | F78: 0 | G78: 0 | H78: 0 | I78: 0 | J78: 0 | K78: =F78*12%+G78*16% -> 0 | L78: =(F78+G78)/E78 -> #DIV/0!
A79: 78 | B79: 0078 | E79: 0 | F79: 0 | G79: 0 | H79: 0 | I79: 0 | J79: 0 | K79: =F79*12%+G79*16% -> 0 | L79: =(F79+G79)/E79 -> #DIV/0!
A80: 79 | B80: 0079 | E80: 0 | F80: 0 | G80: 0 | H80: 0 | I80: 0 | J80: 0 | K80: =F80*12%+G80*16% -> 0 | L80: =(F80+G80)/E80 -> #DIV/0!
A81: 80 | B81: 0080 | E81: 0 | F81: 0 | G81: 0 | H81: 0 | I81: 0 | J81: 0 | K81: =F81*12%+G81*16% -> 0 | L81: =(F81+G81)/E81 -> #DIV/0!
A82: 81 | B82: 0081 | E82: 0 | F82: 0 | G82: 0 | H82: 0 | I82: 0 | J82: 0 | K82: =F82*12%+G82*16% -> 0 | L82: =(F82+G82)/E82 -> #DIV/0!
A83: 82 | B83: 0082 | E83: 0 | F83: 0 | G83: 0 | H83: 0 | I83: 0 | J83: 0 | K83: =F83*12%+G83*16% -> 0 | L83: =(F83+G83)/E83 -> #DIV/0!
E84: =SUM(E2:E83) -> 1781395000 | F84: =SUM(F2:F83) -> 1012740000 | G84: =SUM(G2:G83) -> 84030000 | H84: =SUM(H2:H83) -> 684625000 | I84: =SUM(I2:I83) -> 0 | J84: =SUM(J2:J83) -> 1728 | K84: =SUM(K2:K83) -> 134973600 | L84: =(F84+G84)/E84 -> 0.61568041
F85: =(F84/$E$84) -> 0.56850951 | G85: =(G84/$E$84) -> 0.047170897 | H85: =(H84/$E$84) -> 0.38431959 | I85: =(I84/$E$84) -> 0 | K85: =(K84/(F84+G84)) -> 0.12306464

Sheet RNP|ProctoStop
B1: Масъул | C1: План Ойлик | D1: План кунлик | E1: Факт | F1: 45901 | G1: =F1+1 -> 45902 | H1: =G1+1 -> 45903 | I1: =H1+1 -> 45904 | J1: =I1+1 -> 45905 | K1: =J1+1 -> 45906 | L1: =K1+1 -> 45907 | M1: =L1+1 -> 45908 | N1: =M1+1 -> 45909 | ... AJ1: =AI1+1 -> 45931
A2: Таргет Аюбхон
A3: Бюджет | B3: Акобир | E3: =SUM(F3:AJ3) -> 0
A4: Лидлар сони | B4: Акобир | C4: =+D4*30 -> 0 | D4: =D3/D5 -> 0 | E4: =SUM(F4:AJ4) -> 0
A5: Лид нархи | B5: Акобир | C5: =+C3/C4 -> #DIV/0! | D5: 1 | E5: =+E3/E4 -> #DIV/0! | F5: =F3/F4 -> #DIV/0! | G5: =G3/G4 -> #DIV/0! | H5: =H3/H4 -> #DIV/0! | I5: =I3/I4 -> #DIV/0! | J5: =J3/J4 -> #DIV/0! | K5: =K3/K4 -> #DIV/0! | L5: =L3/L4 -> #DIV/0! | M5: =M3/M4 -> #DIV/0! | ... AJ5: =AJ3/AJ4 -> #DIV/0!
A6: Квал лидлар сони | B6: Акобир | C6: =D6*30 -> 0 | D6: =+D4*D7 -> 0 | E6: =SUM(F6:AJ6) -> 0
A7: Лид/Квал лид | B7: Акобир | C7: =+C6/C4 -> #DIV/0! | D7: 0.6 | E7: =E6/E4 -> #DIV/0! | F7: =F6/F4 -> #DIV/0! | G7: =G6/G4 -> #DIV/0! | H7: =H6/H4 -> #DIV/0! | I7: =I6/I4 -> #DIV/0! | J7: =J6/J4 -> #DIV/0! | K7: =K6/K4 -> #DIV/0! | L7: =L6/L4 -> #DIV/0! | ... AJ7: =AJ6/AJ4 -> #DIV/0!
A8: Недазвон | B8: Акобир | E8: =SUM(F8:AJ8) -> 0
A9: Лид/Недазвон | B9: Акобир | E9: =E8/E4 -> #DIV/0! | F9: =+F8/F4 -> #DIV/0! | G9: =+G8/G4 -> #DIV/0! | H9: =+H8/H4 -> #DIV/0! | I9: =+I8/I4 -> #DIV/0! | J9: =+J8/J4 -> #DIV/0! | K9: =+K8/K4 -> #DIV/0! | L9: =+L8/L4 -> #DIV/0! | M9: =+M8/M4 -> #DIV/0! | ... AJ9: =+AJ8/AJ4 -> #DIV/0!
A10: Сифатсиз | B10: Акобир | E10: =SUM(F10:AJ10) -> 0
A11: Лиддан/Сифатсиз | B11: Акобир | E11: =E10/E4 -> #DIV/0! | F11: =+F10/F4 -> #DIV/0! | G11: =+G10/G4 -> #DIV/0! | H11: =+H10/H4 -> #DIV/0! | I11: =+I10/I4 -> #DIV/0! | J11: =+J10/J4 -> #DIV/0! | K11: =+K10/K4 -> #DIV/0! | L11: =+L10/L4 -> #DIV/0! | M11: =+M10/M4 -> #DIV/0! | ... AJ11: =+AJ10/AJ4 -> #DIV/0!
A12: Квал лид нархи | B12: Акобир | C12: =+C3/C6 -> #DIV/0! | D12: =+D3/D6 -> #DIV/0! | E12: =+E3/E6 -> #DIV/0! | F12: =F3/F6 -> #DIV/0! | G12: =G3/G6 -> #DIV/0! | H12: =H3/H6 -> #DIV/0! | I12: =I3/I6 -> #DIV/0! | J12: =J3/J6 -> #DIV/0! | K12: =K3/K6 -> #DIV/0! | L12: =L3/L6 -> #DIV/0! | M12: =M3/M6 -> #DIV/0! | ... AJ12: =AJ3/AJ6 -> #DIV/0!
A14: Таргет Adbox
A15: Бюджет | B15: Акобир | C15: =D15*30 -> 3600 | D15: 120 | E15: =SUM(F15:AJ15) -> 0
A16: Лидлар сони | B16: Акобир | C16: =D16*30 -> 3600 | D16: =D15/D17 -> 120 | E16: =SUM(F16:AJ16) -> 0
A17: Лид нархи | B17: Акобир | C17: =+C15/C16 -> 1 | D17: 1 | E17: =+E15/E16 -> #DIV/0! | F17: =F15/F16 -> #DIV/0! | G17: =G15/G16 -> #DIV/0! | H17: =H15/H16 -> #DIV/0! | I17: =I15/I16 -> #DIV/0! | J17: =J15/J16 -> #DIV/0! | K17: =K15/K16 -> #DIV/0! | L17: =L15/L16 -> #DIV/0! | M17: =M15/M16 -> #DIV/0! | ... AJ17: =AJ15/AJ16 -> #DIV/0!
A18: Квал лидлар сони | B18: Акобир | C18: =D18*30 -> 2160 | D18: =+D16*D19 -> 72 | E18: =SUM(F18:AJ18) -> 0
A19: Лид/Квал лид | B19: Акобир | C19: =C18/C16 -> 0.6 | D19: 0.6 | E19: =E18/E16 -> #DIV/0! | F19: =F18/F16 -> #DIV/0! | G19: =G18/G16 -> #DIV/0! | H19: =H18/H16 -> #DIV/0! | I19: =I18/I16 -> #DIV/0! | J19: =J18/J16 -> #DIV/0! | K19: =K18/K16 -> #DIV/0! | L19: =L18/L16 -> #DIV/0! | ... AJ19: =AJ18/AJ16 -> #DIV/0!
A20: Недазвон | B20: Акобир | E20: =SUM(F20:AJ20) -> 0
A21: Лид/Недазвон | B21: Акобир | E21: =E20/E16 -> #DIV/0! | F21: =+F20/F16 -> #DIV/0! | G21: =+G20/G16 -> #DIV/0! | H21: =+H20/H16 -> #DIV/0! | I21: =+I20/I16 -> #DIV/0! | J21: =+J20/J16 -> #DIV/0! | K21: =+K20/K16 -> #DIV/0! | L21: =+L20/L16 -> #DIV/0! | M21: =+M20/M16 -> #DIV/0! | ... AJ21: =+AJ20/AJ16 -> #DIV/0!
A22: Сифатсиз | B22: Акобир | E22: =SUM(F22:AJ22) -> 0
A23: Лиддан/Сифатсиз | B23: Акобир | E23: =E22/E16 -> #DIV/0! | F23: =+F22/F16 -> #DIV/0! | G23: =+G22/G16 -> #DIV/0! | H23: =+H22/H16 -> #DIV/0! | I23: =+I22/I16 -> #DIV/0! | J23: =+J22/J16 -> #DIV/0! | K23: =+K22/K16 -> #DIV/0! | L23: =+L22/L16 -> #DIV/0! | M23: =+M22/M16 -> #DIV/0! | ... AJ23: =+AJ22/AJ16 -> #DIV/0!
A24: Квал лид нархи | B24: Акобир | C24: =+C15/C18 -> 1.6666667 | D24: =+D15/D18 -> 1.6666667 | E24: =+E15/E18 -> #DIV/0! | F24: =F15/F18 -> #DIV/0! | G24: =G15/G18 -> #DIV/0! | H24: =H15/H18 -> #DIV/0! | I24: =I15/I18 -> #DIV/0! | J24: =J15/J18 -> #DIV/0! | K24: =K15/K18 -> #DIV/0! | L24: =L15/L18 -> #DIV/0! | M24: =M15/M18 -> #DIV/0! | ... AJ24: =AJ15/AJ18 -> #DIV/0!
A26: Таргет Акобир
A27: Бюджет | B27: Акобир | C27: =D27*30 -> 3600 | D27: 120 | E27: =SUM(F27:AJ27) -> 0
A28: Лидлар сони | B28: Акобир | C28: =D28*30 -> 3600 | D28: =D27/D29 -> 120 | E28: =SUM(F28:AJ28) -> 0
A29: Лид нархи | B29: Акобир | C29: =+C27/C28 -> 1 | D29: 1 | E29: =+E27/E28 -> #DIV/0! | F29: =F27/F28 -> #DIV/0! | G29: =G27/G28 -> #DIV/0! | H29: =H27/H28 -> #DIV/0! | I29: =I27/I28 -> #DIV/0! | J29: =J27/J28 -> #DIV/0! | K29: =K27/K28 -> #DIV/0! | L29: =L27/L28 -> #DIV/0! | M29: =M27/M28 -> #DIV/0! | ... AJ29: =AJ27/AJ28 -> #DIV/0!
A30: Квал лидлар сони | B30: Акобир | C30: =D30*30 -> 2160 | D30: =+D28*D31 -> 72 | E30: =SUM(F30:AJ30) -> 0
A31: Лид/Квал лид | B31: Акобир | C31: =C30/C28 -> 0.6 | D31: 0.6 | E31: =E30/E28 -> #DIV/0! | F31: =F30/F28 -> #DIV/0! | G31: =G30/G28 -> #DIV/0! | H31: =H30/H28 -> #DIV/0! | I31: =I30/I28 -> #DIV/0! | J31: =J30/J28 -> #DIV/0! | K31: =K30/K28 -> #DIV/0! | L31: =L30/L28 -> #DIV/0! | ... AJ31: =AJ30/AJ28 -> #DIV/0!
A32: Недазвон | B32: Акобир | E32: =SUM(F32:AJ32) -> 0
A33: Лид/Недазвон | B33: Акобир | E33: =E32/E28 -> #DIV/0! | F33: =F32/F28 -> #DIV/0! | G33: =G32/G28 -> #DIV/0! | H33: =H32/H28 -> #DIV/0! | I33: =I32/I28 -> #DIV/0! | J33: =J32/J28 -> #DIV/0! | K33: =K32/K28 -> #DIV/0! | L33: =L32/L28 -> #DIV/0! | ... AJ33: =AJ32/AJ28 -> #DIV/0!
A34: Сифатсиз | B34: Акобир | E34: =SUM(F34:AJ34) -> 0
A35: Лиддан/Сифатсиз | B35: Акобир | E35: =E34/E28 -> #DIV/0! | F35: =F34/F28 -> #DIV/0! | G35: =G34/G28 -> #DIV/0! | H35: =H34/H28 -> #DIV/0! | I35: =I34/I28 -> #DIV/0! | J35: =J34/J28 -> #DIV/0! | K35: =K34/K28 -> #DIV/0! | L35: =L34/L28 -> #DIV/0! | ... AJ35: =AJ34/AJ28 -> #DIV/0!
A36: Квал лид нархи | B36: Акобир | C36: =+C27/C30 -> 1.6666667 | D36: =+D27/D30 -> 1.6666667 | E36: =+E27/E30 -> #DIV/0! | F36: =F27/F30 -> #DIV/0! | G36: =G27/G30 -> #DIV/0! | H36: =H27/H30 -> #DIV/0! | I36: =I27/I30 -> #DIV/0! | J36: =J27/J30 -> #DIV/0! | K36: =K27/K30 -> #DIV/0! | L36: =L27/L30 -> #DIV/0! | M36: =M27/M30 -> #DIV/0! | ... AJ36: =AJ27/AJ30 -> #DIV/0!
A38: Limpid Digital
A39: Бюджет | B39: Акобир | C39: =D39*30 -> 3600 | D39: 120 | E39: =SUM(F39:AJ39) -> 115.17 | W39: 21.43 | X39: 23.95 | Y39: 28.68 | Z39: 28.38 | AA39: 12.73
A40: Лидлар сони | B40: Акобир | C40: =D40*30 -> 3600 | D40: =D39/D41 -> 120 | E40: =SUM(F40:AJ40) -> 115 | W40: 23 | X40: 30 | Y40: 27 | Z40: 22 | AA40: 13
A41: Лид нархи | B41: Акобир | C41: =+C39/C40 -> 1 | D41: 1 | E41: =+E39/E40 -> 1.0014783 | F41: =F39/F40 -> #DIV/0! | G41: =G39/G40 -> #DIV/0! | H41: =H39/H40 -> #DIV/0! | I41: =I39/I40 -> #DIV/0! | J41: =J39/J40 -> #DIV/0! | K41: =K39/K40 -> #DIV/0! | L41: =L39/L40 -> #DIV/0! | M41: =M39/M40 -> #DIV/0! | ... AJ41: =AJ39/AJ40 -> #DIV/0!
A42: Квал лидлар сони | B42: Акобир | C42: =D42*30 -> 2160 | D42: =+D40*D43 -> 72 | E42: =SUM(F42:AJ42) -> 5 | W42: 3 | X42: 2
A43: Лид/Квал лид | B43: Акобир | C43: =C42/C40 -> 0.6 | D43: 0.6 | E43: =E42/E40 -> 0.043478261 | F43: =F42/F40 -> #DIV/0! | G43: =G42/G40 -> #DIV/0! | H43: =H42/H40 -> #DIV/0! | I43: =I42/I40 -> #DIV/0! | J43: =J42/J40 -> #DIV/0! | K43: =K42/K40 -> #DIV/0! | L43: =L42/L40 -> #DIV/0! | ... AJ43: =AJ42/AJ40 -> #DIV/0!
...
